Workbook

Sheet Trend Analysis
A3: Row Labels | B3: Order Count | C3: Total Revenue
A4: 2023 | B4: 510 | C4: 552643.24
A5: Jan | B5: 47 | C5: 56685.75
A6: Feb | B6: 37 | C6: 40117.66
A7: Mar | B7: 43 | C7: 48609.37
A8: Apr | B8: 31 | C8: 27751.71
A9: May | B9: 49 | C9: 63836.84
A10: Jun | B10: 45 | C10: 49500.19
A11: Jul | B11: 44 | C11: 42820.66
A12: Aug | B12: 51 | C12: 54352.14
A13: Sep | B13: 29 | C13: 29526.67
A14: Oct | B14: 47 | C14: 52607.85
A15: Nov | B15: 41 | C15: 43079.67
... A37: Grand Total | B37: 1200 | C37: 1264762

Sheet Outlier Detection
A1: TotalPrice Outlier Analysis | B1: Values
A2: Q1 (25th Percentile) | B2: =QUARTILE(Sheet1!N2:N1201,1) -> 410.52
A3: Q3 (75th Percentile) | B3: =QUARTILE(Sheet1!N2:N1201,3) -> 1578.475
A4: IQR (Q3-Q1) | B4: =B3-B2 -> 1167.955
A5: Lower fence (Q1-1.5xIQR) | B5: =B2-(1.5*B4) -> -1341.4125
A6: Upper Fence (Q3+1.5xIQR) | B6: =B3+(1.5*B4) -> 3330.4075
A7: Count of Outliers (Below Lower) | B7: =COUNTIF(Sheet1!N2:N1201,"<"&B5) -> 0
A8: Count of Outliers (Above Upper) | B8: =COUNTIF(Sheet1!N2:N1201,">"&B6) -> 8
A9: Total Outliers | B9: =B7+B8 -> 8
A11: Outlier Summary | B11: Values
A12: Total Orders Analyzed | B12: 1200
A13: Total Outliers Found | B13: =B9 -> 8
A14: % of Orders That are Outliers | B14: =B9/1200 -> 0.0066666667
A15: Outliers below Lower fence | B15: =B7 -> 0
A16: Outliers above Upper fence | B16: =B8 -> 8
A33: Outlier Table
A34: OrderID | B34: Product | C34: TotalPrice
A35: ORD200107 | B35: Printer | C35: 3353.75
A36: ORD200326 | B36: Laptop | C36: 3352.4
A37: ORD200328 | B37: Tablet | C37: 3370.2
A38: ORD200469 | B38: Chair | C38: 3384.9
A39: ORD200632 | B39: Laptop | C39: 3390.8
A40: ORD200789 | B40: Tablet | C40: 3456.4
A41: ORD201065 | B41: Printer | C41: 3334
A42: ORD201122 | B42: Monitor | C42: 3390.95

Sheet Sheet1
A1: OrderID | B1: Date | C1: CustomerID | D1: Product | E1: Quantity | F1: UnitPrice | G1: ShippingAddress | H1: PaymentMethod | I1: OrderStatus | J1: TrackingNumber | K1: ItemsInCart | L1: CouponCode | M1: ReferralSource | N1: TotalPrice
A2: ORD200000 | B2: 44930 | C2: C72649 | D2: Monitor | E2: 5 | F2: 570.62 | G2: 928 Main St | H2: Debit Card | I2: Shipped | J2: TRK37947903 | K2: 7 | L2: SAVE10 | M2: Instagram | N2: 2853.1
A3: ORD200001 | B3: 45527 | C3: C75739 | D3: Phone | E3: 2 | F3: 151.35 | G3: 823 Main St | H3: Online | I3: Shipped | J3: TRK91186779 | K3: 3 | L3: SAVE10 | M3: Referral | N3: 302.7
A4: ORD200002 | B4: 45349 | C4: C81728 | D4: Tablet | E4: 5 | F4: 550.68 | G4: 512 Main St | H4: Credit Card | I4: Cancelled | J4: TRK42903982 | K4: 8 | L4: FREESHIP | M4: Email | N4: 2753.4
A5: ORD200003 | B5: 45214 | C5: C33540 | D5: Chair | E5: 1 | F5: 273.19 | G5: 275 Main St | H5: Debit Card | I5: Returned | J5: TRK62788070 | K5: 5 | L5: SAVE10 | M5: Facebook | N5: 273.19
A6: ORD200004 | B6: 45785 | C6: C81840 | D6: Printer | E6: 4 | F6: 626.01 | G6: 668 Main St | H6: Online | I6: Delivered | J6: TRK29241424 | K6: 8 | L6: SAVE10 | M6: Email | N6: 2504.04
A7: ORD200005 | B7: 45222 | C7: C37249 | D7: Phone | E7: 2 | F7: 245.86 | G7: 934 Main St | H7: Credit Card | I7: Shipped | J7: TRK72976927 | K7: 4 | L7: SAVE10 | M7: Instagram | N7: 491.72
A8: ORD200006 | B8: 45825 | C8: C83492 | D8: Laptop | E8: 1 | F8: 664.42 | G8: 986 Main St | H8: Gift Card | I8: Returned | J8: TRK96417362 | K8: 6 | L8: SAVE10 | M8: Facebook | N8: 664.42
A9: ORD200007 | B9: 45058 | C9: C41460 | D9: Monitor | E9: 5 | F9: 149.55 | G9: 706 Main St | H9: Cash | I9: Shipped | J9: TRK78809193 | K9: 9 | L9: FREESHIP | M9: Facebook | N9: 747.75
A10: ORD200008 | B10: 45749 | C10: C26817 | D10: Phone | E10: 2 | F10: 134.28 | G10: 904 Main St | H10: Gift Card | I10: Cancelled | J10: TRK61042692 | K10: 2 | M10: Email | N10: 268.56
A11: ORD200009 | B11: 45251 | C11: C31946 | D11: Desk | E11: 4 | F11: 509.38 | G11: 102 Main St | H11: Credit Card | I11: Shipped | J11: TRK33478363 | K11: 6 | L11: SAVE10 | M11: Google | N11: 2037.52
A12: ORD200010 | B12: 45289 | C12: C43443 | D12: Tablet | E12: 5 | F12: 625.97 | G12: 333 Main St | H12: Credit Card | I12: Returned | J12: TRK98859248 | K12: 9 | L12: WINTER15 | M12: Instagram | N12: 3129.85
A13: ORD200011 | B13: 45339 | C13: C93861 | D13: Monitor | E13: 3 | F13: 49.14 | G13: 831 Main St | H13: Online | I13: Returned | J13: TRK48234646 | K13: 7 | L13: SAVE10 | M13: Email | N13: 147.42
A14: ORD200012 | B14: 45580 | C14: C38785 | D14: Monitor | E14: 2 | F14: 180.5 | G14: 179 Main St | H14: Debit Card | I14: Pending | J14: TRK20419991 | K14: 6 | L14: FREESHIP | M14: Referral | N14: 361
A15: ORD200013 | B15: 45168 | C15: C88348 | D15: Laptop | E15: 3 | F15: 201.49 | G15: 903 Main St | H15: Credit Card | I15: Returned | J15: TRK81913874 | K15: 4 | L15: FREESHIP | M15: Facebook | N15: 604.47
A16: ORD200014 | B16: 45012 | C16: C98474 | D16: Tablet | E16: 2 | F16: 393.33 | G16: 980 Main St | H16: Debit Card | I16: Pending | J16: TRK79186539 | K16: 3 | L16: SAVE10 | M16: Instagram | N16: 786.66
A17: ORD200015 | B17: 45124 | C17: C39416 | D17: Printer | E17: 1 | F17: 473.96 | G17: 942 Main St | H17: Cash | I17: Delivered | J17: TRK54930938 | K17: 3 | M17: Google | N17: 473.96
A18: ORD200016 | B18: 44950 | C18: C28976 | D18: Printer | E18: 2 | F18: 533.81 | G18: 914 Main St | H18: Credit Card | I18: Pending | J18: TRK13194259 | K18: 3 | L18: FREESHIP | M18: Email | N18: 1067.62
A19: ORD200017 | B19: 45353 | C19: C60672 | D19: Tablet | E19: 1 | F19: 423.4 | G19: 382 Main St | H19: Debit Card | I19: Shipped | J19: TRK11972116 | K19: 3 | M19: Referral | N19: 423.4
A20: ORD200018 | B20: 45742 | C20: C84329 | D20: Desk | E20: 1 | F20: 431.44 | G20: 891 Main St | H20: Gift Card | I20: Pending | J20: TRK65191045 | K20: 3 | L20: SAVE10 | M20: Facebook | N20: 431.44
A21: ORD200019 | B21: 44949 | C21: C14552 | D21: Monitor | E21: 5 | F21: 224 | G21: 273 Main St | H21: Cash | I21: Returned | J21: TRK59101365 | K21: 9 | L21: SAVE10 | M21: Google | N21: 1120
A22: ORD200020 | B22: 45054 | C22: C54829 | D22: Chair | E22: 5 | F22: 62.51 | G22: 587 Main St | H22: Cash | I22: Pending | J22: TRK16718651 | K22: 9 | L22: WINTER15 | M22: Instagram | N22: 312.55
A23: ORD200021 | B23: 45613 | C23: C99023 | D23: Monitor | E23: 4 | F23: 342.95 | G23: 569 Main St | H23: Cash | I23: Delivered | J23: TRK52646983 | K23: 6 | M23: Google | N23: 1371.8
A24: ORD200022 | B24: 44955 | C24: C34416 | D24: Monitor | E24: 2 | F24: 49.62 | G24: 633 Main St | H24: Online | I24: Pending | J24: TRK75937350 | K24: 2 | L24: SAVE10 | M24: Google | N24: 99.24
A25: ORD200023 | B25: 45756 | C25: C42372 | D25: Phone | E25: 4 | F25: 273.25 | G25: 755 Main St | H25: Debit Card | I25: Cancelled | J25: TRK36168083 | K25: 5 | L25: FREESHIP | M25: Referral | N25: 1093
A26: ORD200024 | B26: 45595 | C26: C17470 | D26: Laptop | E26: 2 | F26: 230.95 | G26: 956 Main St | H26: Online | I26: Delivered | J26: TRK28775057 | K26: 3 | L26: WINTER15 | M26: Referral | N26: 461.9
A27: ORD200025 | B27: 45497 | C27: C42577 | D27: Monitor | E27: 1 | F27: 399.98 | G27: 709 Main St | H27: Debit Card | I27: Delivered | J27: TRK69423327 | K27: 3 | L27: WINTER15 | M27: Email | N27: 399.98
A28: ORD200026 | B28: 45357 | C28: C21944 | D28: Laptop | E28: 5 | F28: 59.55 | G28: 296 Main St | H28: Online | I28: Delivered | J28: TRK80276812 | K28: 6 | M28: Referral | N28: 297.75
A29: ORD200027 | B29: 45344 | C29: C97593 | D29: Printer | E29: 1 | F29: 472.74 | G29: 881 Main St | H29: Online | I29: Shipped | J29: TRK89117573 | K29: 6 | L29: WINTER15 | M29: Google | N29: 472.74
A30: ORD200028 | B30: 45251 | C30: C59823 | D30: Phone | E30: 4 | F30: 160.07 | G30: 568 Main St | H30: Online | I30: Pending | J30: TRK65895539 | K30: 5 | M30: Email | N30: 640.28
A31: ORD200029 | B31: 45555 | C31: C33260 | D31: Desk | E31: 3 | F31: 423.53 | G31: 930 Main St | H31: Credit Card | I31: Delivered | J31: TRK59744090 | K31: 6 | L31: SAVE10 | M31: Referral | N31: 1270.59
A32: ORD200030 | B32: 45738 | C32: C44267 | D32: Monitor | E32: 2 | F32: 426.7 | G32: 895 Main St | H32: Online | I32: Pending | J32: TRK54751444 | K32: 5 | L32: SAVE10 | M32: Referral | N32: 853.4
A33: ORD200031 | B33: 45107 | C33: C26445 | D33: Chair | E33: 3 | F33: 500.08 | G33: 996 Main St | H33: Debit Card | I33: Returned | J33: TRK31229981 | K33: 6 | M33: Facebook | N33: 1500.24
A34: ORD200032 | B34: 45047 | C34: C12388 | D34: Tablet | E34: 5 | F34: 536.72 | G34: 830 Main St | H34: Cash | I34: Delivered | J34: TRK99261395 | K34: 10 | M34: Email | N34: 2683.6
A35: ORD200033 | B35: 45082 | C35: C52184 | D35: Chair | E35: 1 | F35: 162.77 | G35: 912 Main St | H35: Online | I35: Cancelled | J35: TRK73312471 | K35: 4 | L35: WINTER15 | M35: Facebook | N35: 162.77
A36: ORD200034 | B36: 44933 | C36: C67195 | D36: Chair | E36: 4 | F36: 576.52 | G36: 926 Main St | H36: Credit Card | I36: Pending | J36: TRK55467915 | K36: 5 | L36: WINTER15 | M36: Facebook | N36: 2306.08
A37: ORD200035 | B37: 45633 | C37: C50304 | D37: Monitor | E37: 2 | F37: 465.15 | G37: 128 Main St | H37: Online | I37: Shipped | J37: TRK46850888 | K37: 2 | L37: SAVE10 | M37: Facebook | N37: 930.3
A38: ORD200036 | B38: 45785 | C38: C59337 | D38: Laptop | E38: 2 | F38: 534.43 | G38: 465 Main St | H38: Debit Card | I38: Pending | J38: TRK50961250 | K38: 5 | M38: Facebook | N38: 1068.86
A39: ORD200037 | B39: 45579 | C39: C10054 | D39: Laptop | E39: 2 | F39: 76.74 | G39: 409 Main St | H39: Cash | I39: Returned | J39: TRK94005261 | K39: 7 | L39: SAVE10 | M39: Instagram | N39: 153.48
A40: ORD200038 | B40: 45645 | C40: C15924 | D40: Laptop | E40: 1 | F40: 245.89 | G40: 549 Main St | H40: Debit Card | I40: Delivered | J40: TRK14835975 | K40: 3 | L40: SAVE10 | M40: Google | N40: 245.89
...

Sheet Data Profile
A1: Dataset Overview | B1: Column1
A2: Total Rows | B2: =COUNTA(Sheet1!A:A)-1 -> 1200
A3: Total Columns | B3: 14
A4: Data Range (Start) | B4: =MIN(Sheet1!B:B) -> 44927
A5: Data Range (End) | B5: =MAX(Sheet1!B:B) -> 45838
A7: Column Name | B7: Data Type | C7: Null Count | D7: Notes
A8: Order ID | B8: Text | C8: 0 | D8: Unique Identifier
A9: Date | B9: Date | C9: 0 | D9: Order date
A10: CustomerID | B10: Text | C10: 0 | D10: Unique per person
A11: Product | B11: Text | C11: 0 | D11: 7 product types
A12: Quantity | B12: Number | C12: 0 | D12: Range: 1-5
A13: UnitPrice | B13: Number | C13: 0 | D13: Price per item
A14: Shipping Address | B14: Text | C14: 0 | D14: Street address
A15: Payment Method | B15: Text | C15: 0 | D15: 5 payment types
A16: OrderStatus | B16: Text | C16: 0 | D16: 5 status types
A17: TrackingNumber | B17: Text | C17: 0 | D17: Logistics code
A18: ItemsInCart | B18: Number | C18: 0 | D18: Range: 1-10
A19: CouponCode | B19: Text | C19: =ROWS(Sheet1!L2:L1201)-COUNTA(Sheet1!L2:L1201) -> 309 | D19: Has blank values
A20: Referral Source | B20: Text | C20: 0 | D20: 5 sources
A21: Total Price | B21: Number | C21: 0 | D21: Qty x UnitPrice

Sheet Descriptive Statistics
A1: Metrics | B1: Quantity | C1: UnitPrice | D1: TotalPrice | E1: ItemsInCart
A2: Count | B2: =COUNTA(Sheet1!E2:E1201) -> 1200 | C2: =COUNTA(Sheet1!F2:F1201) -> 1200 | D2: =COUNTA(Sheet1!N2:N1201) -> 1200 | E2: =COUNTA(Sheet1!K2:K1201) -> 1200
A3: Mean | B3: =AVERAGE(Sheet1!E2:E1201) -> 2.9458333 | C3: =AVERAGE(Sheet1!F2:F1201) -> 356.41275 | D3: =AVERAGE(Sheet1!N2:N1201) -> 1053.9683 | E3: =AVERAGE(Sheet1!K2:K1201) -> 5.485
A4: Median | B4: =MEDIAN(Sheet1!E2:E1201) -> 3 | C4: =MEDIAN(Sheet1!F2:F1201) -> 364.21 | D4: =MEDIAN(Sheet1!N2:N1201) -> 823.615 | E4: =MEDIAN(Sheet1!K2:K1201) -> 5
A5: Mode | B5: =MODE(Sheet1!E2:E1201) -> 1 | C5: =MODE(Sheet1!F2:F1201) -> 127.18 | D5: =MODE(Sheet1!N2:N1201) -> 635.9 | E5: =MODE(Sheet1!K2:K1201) -> 5
A6: Min | B6: =MIN(Sheet1!E2:E1201) -> 1 | C6: =MIN(Sheet1!F2:F1201) -> 11.39 | D6: =MIN(Sheet1!N2:N1201) -> 11.39 | E6: =MIN(Sheet1!K2:K1201) -> 1
A7: Max | B7: =MAX(Sheet1!E2:E1201) -> 5 | C7: =MAX(Sheet1!F2:F1201) -> 699.93 | D7: =MAX(Sheet1!N2:N1201) -> 3456.4 | E7: =MAX(Sheet1!K2:K1201) -> 10
A8: Std Dev | B8: =STDEV(Sheet1!E2:E1201) -> 1.4075571 | C8: =STDEV(Sheet1!F2:F1201) -> 197.17715 | D8: =STDEV(Sheet1!N2:N1201) -> 819.85656 | E8: =STDEV(Sheet1!K2:K1201) -> 2.2819833
A9: Range | B9: =B7-B6 -> 4 | C9: =C7-C6 -> 688.54 | D9: =D7-D6 -> 3445.01 | E9: =E7-E6 -> 9

Sheet Categorical Analysis
B1: Product Distribution
A2: Product | B2: Order Count | C2: % of Total
A3: Monitor | B3: =COUNTIF(Sheet1!$D:$D,"Monitor") -> 163 | C3: =B3/$B$10 -> 0.13583333
A4: Phone | B4: =COUNTIF(Sheet1!$D:$D,"Phone") -> 156 | C4: =B4/$B$10 -> 0.13
A5: Tablet | B5: =COUNTIF(Sheet1!$D:$D,"Tablet") -> 179 | C5: =B5/$B$10 -> 0.14916667
A6: Laptop | B6: =COUNTIF(Sheet1!$D:$D,"Laptop") -> 173 | C6: =B6/$B$10 -> 0.14416667
A7: Printer | B7: =COUNTIF(Sheet1!$D:$D,"Printer") -> 181 | C7: =B7/$B$10 -> 0.15083333
A8: Chair | B8: =COUNTIF(Sheet1!$D:$D,"Chair") -> 178 | C8: =B8/$B$10 -> 0.14833333
A9: Desk | B9: =COUNTIF(Sheet1!$D:$D,"Desk") -> 170 | C9: =B9/$B$10 -> 0.14166667
A10: Total | B10: =SUM(B3:B9) -> 1200
B12: Order Status Distribution
A13: Order Status | B13: Count | C13: % of Total
A14: Delivered | B14: =COUNTIF(Sheet1!$I:$I,"Delivered") -> 231 | C14: =B14/$B$19 -> 0.1925
A15: Shipped | B15: =COUNTIF(Sheet1!$I:$I,"Shipped") -> 235 | C15: =B15/$B$19 -> 0.19583333
A16: Pending | B16: =COUNTIF(Sheet1!$I:$I,"Pending") -> 237 | C16: =B16/$B$19 -> 0.1975
A17: Cancelled | B17: =COUNTIF(Sheet1!$I:$I,"Cancelled") -> 250 | C17: =B17/$B$19 -> 0.20833333
A18: Returned | B18: =COUNTIF(Sheet1!$I:$I,"Returned") -> 247 | C18: =B18/$B$19 -> 0.20583333
A19: Total | B19: =SUM(B14:B18) -> 1200
B21: Payment Method Distribution
A22: Payment Method | B22: Count | C22: % of Total
A23: Credit Card | B23: =COUNTIF(Sheet1!$H:$H,"Credit Card") -> 234 | C23: =B23/$B$28 -> 0.195
A24: Debit Card | B24: =COUNTIF(Sheet1!$H:$H,"Debit Card") -> 232 | C24: =B24/$B$28 -> 0.19333333
A25: Cash | B25: =COUNTIF(Sheet1!$H:$H,"Cash") -> 246 | C25: =B25/$B$28 -> 0.205
A26: Online | B26: =COUNTIF(Sheet1!$H:$H,"Online") -> 258 | C26: =B26/$B$28 -> 0.215
A27: Gift Card | B27: =COUNTIF(Sheet1!$H:$H,"Gift Card") -> 230 | C27: =B27/$B$28 -> 0.19166667
A28: Total | B28: =SUM(B23:B27) -> 1200
B30: Referral Source Distribution
A31: Referral Source | B31: Count | C31: % of Total
A32: Facebook | B32: =COUNTIF(Sheet1!$M:$M,"Facebook") -> 228 | C32: =B32/$B$37 -> 0.19
A33: Instagram | B33: =COUNTIF(Sheet1!$M:$M,"Instagram") -> 259 | C33: =B33/$B$37 -> 0.21583333
A34: Google | B34: =COUNTIF(Sheet1!$M:$M,"Google") -> 241 | C34: =B34/$B$37 -> 0.20083333
A35: Email | B35: =COUNTIF(Sheet1!$M:$M,"Email") -> 250 | C35: =B35/$B$37 -> 0.20833333
A36: Referral | B36: =COUNTIF(Sheet1!$M:$M,"Referral") -> 222 | C36: =B36/$B$37 -> 0.185
A37: Total | B37: =SUM(B32:B36) -> 1200

Sheet Table2
A1: OrderID | B1: Date | C1: CustomerID | D1: Product | E1: Quantity | F1: UnitPrice | G1: ShippingAddress | H1: PaymentMethod | I1: OrderStatus | J1: TrackingNumber | K1: ItemsInCart | L1: CouponCode | M1: ReferralSource | N1: TotalPrice
A2: ORD200000 | B2: 44930 | C2: C72649 | D2: Monitor | E2: 5 | F2: 570.62 | G2: 928 Main St | H2: Debit Card | I2: Shipped | J2: TRK37947903 | K2: 7 | L2: SAVE10 | M2: Instagram | N2: 2853.1
A3: ORD200001 | B3: 45527 | C3: C75739 | D3: Phone | E3: 2 | F3: 151.35 | G3: 823 Main St | H3: Online | I3: Shipped | J3: TRK91186779 | K3: 3 | L3: SAVE10 | M3: Referral | N3: 302.7
A4: ORD200002 | B4: 45349 | C4: C81728 | D4: Tablet | E4: 5 | F4: 550.68 | G4: 512 Main St | H4: Credit Card | I4: Cancelled | J4: TRK42903982 | K4: 8 | L4: FREESHIP | M4: Email | N4: 2753.4
A5: ORD200003 | B5: 45214 | C5: C33540 | D5: Chair | E5: 1 | F5: 273.19 | G5: 275 Main St | H5: Debit Card | I5: Returned | J5: TRK62788070 | K5: 5 | L5: SAVE10 | M5: Facebook | N5: 273.19
A6: ORD200004 | B6: 45785 | C6: C81840 | D6: Printer | E6: 4 | F6: 626.01 | G6: 668 Main St | H6: Online | I6: Delivered | J6: TRK29241424 | K6: 8 | L6: SAVE10 | M6: Email | N6: 2504.04
A7: ORD200005 | B7: 45222 | C7: C37249 | D7: Phone | E7: 2 | F7: 245.86 | G7: 934 Main St | H7: Credit Card | I7: Shipped | J7: TRK72976927 | K7: 4 | L7: SAVE10 | M7: Instagram | N7: 491.72
A8: ORD200006 | B8: 45825 | C8: C83492 | D8: Laptop | E8: 1 | F8: 664.42 | G8: 986 Main St | H8: Gift Card | I8: Returned | J8: TRK96417362 | K8: 6 | L8: SAVE10 | M8: Facebook | N8: 664.42
A9: ORD200007 | B9: 45058 | C9: C41460 | D9: Monitor | E9: 5 | F9: 149.55 | G9: 706 Main St | H9: Cash | I9: Shipped | J9: TRK78809193 | K9: 9 | L9: FREESHIP | M9: Facebook | N9: 747.75
A10: ORD200008 | B10: 45749 | C10: C26817 | D10: Phone | E10: 2 | F10: 134.28 | G10: 904 Main St | H10: Gift Card | I10: Cancelled | J10: TRK61042692 | K10: 2 | L10: No coupon code | M10: Email | N10: 268.56
A11: ORD200009 | B11: 45251 | C11: C31946 | D11: Desk | E11: 4 | F11: 509.38 | G11: 102 Main St | H11: Credit Card | I11: Shipped | J11: TRK33478363 | K11: 6 | L11: SAVE10 | M11: Google | N11: 2037.52
A12: ORD200010 | B12: 45289 | C12: C43443 | D12: Tablet | E12: 5 | F12: 625.97 | G12: 333 Main St | H12: Credit Card | I12: Returned | J12: TRK98859248 | K12: 9 | L12: WINTER15 | M12: Instagram | N12: 3129.85
A13: ORD200011 | B13: 45339 | C13: C93861 | D13: Monitor | E13: 3 | F13: 49.14 | G13: 831 Main St | H13: Online | I13: Returned | J13: TRK48234646 | K13: 7 | L13: SAVE10 | M13: Email | N13: 147.42
... A1201: ORD201199 | B1201: 45088 | C1201: C57502 | D1201: Tablet | E1201: 4 | F1201: 560.58 | G1201: 201 Main St | H1201: Gift Card | I1201: Returned | J1201: TRK51116746 | K1201: 6 | L1201: SAVE10 | M1201: Referral | N1201: 2242.32

Sheet Sheet2
A1: OrderID | B1: Date | C1: CustomerID | D1: Product | E1: Quantity | F1: UnitPrice | G1: ShippingAddress | H1: PaymentMethod | I1: OrderStatus | J1: TrackingNumber | K1: ItemsInCart | L1: CouponCode | M1: ReferralSource | N1: TotalPrice
A2: ORD200000 | B2: 44930 | C2: C72649 | D2: Monitor | E2: 5 | F2: 570.62 | G2: 928 Main St | H2: Debit Card | I2: Shipped | J2: TRK37947903 | K2: 7 | L2: SAVE10 | M2: Instagram | N2: 2853.1
A3: ORD200001 | B3: 45527 | C3: C75739 | D3: Phone | E3: 2 | F3: 151.35 | G3: 823 Main St | H3: Online | I3: Shipped | J3: TRK91186779 | K3: 3 | L3: SAVE10 | M3: Referral | N3: 302.7
A4: ORD200002 | B4: 45349 | C4: C81728 | D4: Tablet | E4: 5 | F4: 550.68 | G4: 512 Main St | H4: Credit Card | I4: Cancelled | J4: TRK42903982 | K4: 8 | L4: FREESHIP | M4: Email | N4: 2753.4
A5: ORD200003 | B5: 45214 | C5: C33540 | D5: Chair | E5: 1 | F5: 273.19 | G5: 275 Main St | H5: Debit Card | I5: Returned | J5: TRK62788070 | K5: 5 | L5: SAVE10 | M5: Facebook | N5: 273.19
A6: ORD200004 | B6: 45785 | C6: C81840 | D6: Printer | E6: 4 | F6: 626.01 | G6: 668 Main St | H6: Online | I6: Delivered | J6: TRK29241424 | K6: 8 | L6: SAVE10 | M6: Email | N6: 2504.04
A7: ORD200005 | B7: 45222 | C7: C37249 | D7: Phone | E7: 2 | F7: 245.86 | G7: 934 Main St | H7: Credit Card | I7: Shipped | J7: TRK72976927 | K7: 4 | L7: SAVE10 | M7: Instagram | N7: 491.72
A8: ORD200006 | B8: 45825 | C8: C83492 | D8: Laptop | E8: 1 | F8: 664.42 | G8: 986 Main St | H8: Gift Card | I8: Returned | J8: TRK96417362 | K8: 6 | L8: SAVE10 | M8: Facebook | N8: 664.42
A9: ORD200007 | B9: 45058 | C9: C41460 | D9: Monitor | E9: 5 | F9: 149.55 | G9: 706 Main St | H9: Cash | I9: Shipped | J9: TRK78809193 | K9: 9 | L9: FREESHIP | M9: Facebook | N9: 747.75
A10: ORD200008 | B10: 45749 | C10: C26817 | D10: Phone | E10: 2 | F10: 134.28 | G10: 904 Main St | H10: Gift Card | I10: Cancelled | J10: TRK61042692 | K10: 2 | M10: Email | N10: 268.56
A11: ORD200009 | B11: 45251 | C11: C31946 | D11: Desk | E11: 4 | F11: 509.38 | G11: 102 Main St | H11: Credit Card | I11: Shipped | J11: TRK33478363 | K11: 6 | L11: SAVE10 | M11: Google | N11: 2037.52
A12: ORD200010 | B12: 45289 | C12: C43443 | D12: Tablet | E12: 5 | F12: 625.97 | G12: 333 Main St | H12: Credit Card | I12: Returned | J12: TRK98859248 | K12: 9 | L12: WINTER15 | M12: Instagram | N12: 3129.85
A13: ORD200011 | B13: 45339 | C13: C93861 | D13: Monitor | E13: 3 | F13: 49.14 | G13: 831 Main St | H13: Online | I13: Returned | J13: TRK48234646 | K13: 7 | L13: SAVE10 | M13: Email | N13: 147.42
A14: ORD200012 | B14: 45580 | C14: C38785 | D14: Monitor | E14: 2 | F14: 180.5 | G14: 179 Main St | H14: Debit Card | I14: Pending | J14: TRK20419991 | K14: 6 | L14: FREESHIP | M14: Referral | N14: 361
A15: ORD200013 | B15: 45168 | C15: C88348 | D15: Laptop | E15: 3 | F15: 201.49 | G15: 903 Main St | H15: Credit Card | I15: Returned | J15: TRK81913874 | K15: 4 | L15: FREESHIP | M15: Facebook | N15: 604.47
A16: ORD200014 | B16: 45012 | C16: C98474 | D16: Tablet | E16: 2 | F16: 393.33 | G16: 980 Main St | H16: Debit Card | I16: Pending | J16: TRK79186539 | K16: 3 | L16: SAVE10 | M16: Instagram | N16: 786.66
A17: ORD200015 | B17: 45124 | C17: C39416 | D17: Printer | E17: 1 | F17: 473.96 | G17: 942 Main St | H17: Cash | I17: Delivered | J17: TRK54930938 | K17: 3 | M17: Google | N17: 473.96
A18: ORD200016 | B18: 44950 | C18: C28976 | D18: Printer | E18: 2 | F18: 533.81 | G18: 914 Main St | H18: Credit Card | I18: Pending | J18: TRK13194259 | K18: 3 | L18: FREESHIP | M18: Email | N18: 1067.62
A19: ORD200017 | B19: 45353 | C19: C60672 | D19: Tablet | E19: 1 | F19: 423.4 | G19: 382 Main St | H19: Debit Card | I19: Shipped | J19: TRK11972116 | K19: 3 | M19: Referral | N19: 423.4
A20: ORD200018 | B20: 45742 | C20: C84329 | D20: Desk | E20: 1 | F20: 431.44 | G20: 891 Main St | H20: Gift Card | I20: Pending | J20: TRK65191045 | K20: 3 | L20: SAVE10 | M20: Facebook | N20: 431.44
A21: ORD200019 | B21: 44949 | C21: C14552 | D21: Monitor | E21: 5 | F21: 224 | G21: 273 Main St | H21: Cash | I21: Returned | J21: TRK59101365 | K21: 9 | L21: SAVE10 | M21: Google | N21: 1120
A22: ORD200020 | B22: 45054 | C22: C54829 | D22: Chair | E22: 5 | F22: 62.51 | G22: 587 Main St | H22: Cash | I22: Pending | J22: TRK16718651 | K22: 9 | L22: WINTER15 | M22: Instagram | N22: 312.55
A23: ORD200021 | B23: 45613 | C23: C99023 | D23: Monitor | E23: 4 | F23: 342.95 | G23: 569 Main St | H23: Cash | I23: Delivered | J23: TRK52646983 | K23: 6 | M23: Google | N23: 1371.8
A24: ORD200022 | B24: 44955 | C24: C34416 | D24: Monitor | E24: 2 | F24: 49.62 | G24: 633 Main St | H24: Online | I24: Pending | J24: TRK75937350 | K24: 2 | L24: SAVE10 | M24: Google | N24: 99.24
A25: ORD200023 | B25: 45756 | C25: C42372 | D25: Phone | E25: 4 | F25: 273.25 | G25: 755 Main St | H25: Debit Card | I25: Cancelled | J25: TRK36168083 | K25: 5 | L25: FREESHIP | M25: Referral | N25: 1093
A26: ORD200024 | B26: 45595 | C26: C17470 | D26: Laptop | E26: 2 | F26: 230.95 | G26: 956 Main St | H26: Online | I26: Delivered | J26: TRK28775057 | K26: 3 | L26: WINTER15 | M26: Referral | N26: 461.9
A27: ORD200025 | B27: 45497 | C27: C42577 | D27: Monitor | E27: 1 | F27: 399.98 | G27: 709 Main St | H27: Debit Card | I27: Delivered | J27: TRK69423327 | K27: 3 | L27: WINTER15 | M27: Email | N27: 399.98
A28: ORD200026 | B28: 45357 | C28: C21944 | D28: Laptop | E28: 5 | F28: 59.55 | G28: 296 Main St | H28: Online | I28: Delivered | J28: TRK80276812 | K28: 6 | M28: Referral | N28: 297.75
A29: ORD200027 | B29: 45344 | C29: C97593 | D29: Printer | E29: 1 | F29: 472.74 | G29: 881 Main St | H29: Online | I29: Shipped | J29: TRK89117573 | K29: 6 | L29: WINTER15 | M29: Google | N29: 472.74
A30: ORD200028 | B30: 45251 | C30: C59823 | D30: Phone | E30: 4 | F30: 160.07 | G30: 568 Main St | H30: Online | I30: Pending | J30: TRK65895539 | K30: 5 | M30: Email | N30: 640.28
A31: ORD200029 | B31: 45555 | C31: C33260 | D31: Desk | E31: 3 | F31: 423.53 | G31: 930 Main St | H31: Credit Card | I31: Delivered | J31: TRK59744090 | K31: 6 | L31: SAVE10 | M31: Referral | N31: 1270.59
A32: ORD200030 | B32: 45738 | C32: C44267 | D32: Monitor | E32: 2 | F32: 426.7 | G32: 895 Main St | H32: Online | I32: Pending | J32: TRK54751444 | K32: 5 | L32: SAVE10 | M32: Referral | N32: 853.4
A33: ORD200031 | B33: 45107 | C33: C26445 | D33: Chair | E33: 3 | F33: 500.08 | G33: 996 Main St | H33: Debit Card | I33: Returned | J33: TRK31229981 | K33: 6 | M33: Facebook | N33: 1500.24
A34: ORD200032 | B34: 45047 | C34: C12388 | D34: Tablet | E34: 5 | F34: 536.72 | G34: 830 Main St | H34: Cash | I34: Delivered | J34: TRK99261395 | K34: 10 | M34: Email | N34: 2683.6
A35: ORD200033 | B35: 45082 | C35: C52184 | D35: Chair | E35: 1 | F35: 162.77 | G35: 912 Main St | H35: Online | I35: Cancelled | J35: TRK73312471 | K35: 4 | L35: WINTER15 | M35: Facebook | N35: 162.77
A36: ORD200034 | B36: 44933 | C36: C67195 | D36: Chair | E36: 4 | F36: 576.52 | G36: 926 Main St | H36: Credit Card | I36: Pending | J36: TRK55467915 | K36: 5 | L36: WINTER15 | M36: Facebook | N36: 2306.08
A37: ORD200035 | B37: 45633 | C37: C50304 | D37: Monitor | E37: 2 | F37: 465.15 | G37: 128 Main St | H37: Online | I37: Shipped | J37: TRK46850888 | K37: 2 | L37: SAVE10 | M37: Facebook | N37: 930.3
A38: ORD200036 | B38: 45785 | C38: C59337 | D38: Laptop | E38: 2 | F38: 534.43 | G38: 465 Main St | H38: Debit Card | I38: Pending | J38: TRK50961250 | K38: 5 | M38: Facebook | N38: 1068.86
A39: ORD200037 | B39: 45579 | C39: C10054 | D39: Laptop | E39: 2 | F39: 76.74 | G39: 409 Main St | H39: Cash | I39: Returned | J39: TRK94005261 | K39: 7 | L39: SAVE10 | M39: Instagram | N39: 153.48
A40: ORD200038 | B40: 45645 | C40: C15924 | D40: Laptop | E40: 1 | F40: 245.89 | G40: 549 Main St | H40: Debit Card | I40: Delivered | J40: TRK14835975 | K40: 3 | L40: SAVE10 | M40: Google | N40: 245.89
...
